[2023-12-10T17:38:52.224+0500] {taskinstance.py:1159} INFO - Dependencies all met for dep_context=non-requeueable deps ti=<TaskInstance: test.merge_df manual__2023-12-10T12:33:28.883629+00:00 [queued]>
[2023-12-10T17:38:52.236+0500] {taskinstance.py:1159} INFO - Dependencies all met for dep_context=requeueable deps ti=<TaskInstance: test.merge_df manual__2023-12-10T12:33:28.883629+00:00 [queued]>
[2023-12-10T17:38:52.236+0500] {taskinstance.py:1361} INFO - Starting attempt 2 of 2
[2023-12-10T17:38:52.264+0500] {taskinstance.py:1382} INFO - Executing <Task(BashOperator): merge_df> on 2023-12-10 12:33:28.883629+00:00
[2023-12-10T17:38:52.267+0500] {standard_task_runner.py:57} INFO - Started process 7190 to run task
[2023-12-10T17:38:52.288+0500] {standard_task_runner.py:84} INFO - Running: ['airflow', 'tasks', 'run', 'test', 'merge_df', 'manual__2023-12-10T12:33:28.883629+00:00', '--job-id', '14', '--raw', '--subdir', 'DAGS_FOLDER/test.py', '--cfg-path', '/tmp/tmpmc_oj_0u']
[2023-12-10T17:38:52.289+0500] {standard_task_runner.py:85} INFO - Job 14: Subtask merge_df
[2023-12-10T17:38:52.363+0500] {task_command.py:416} INFO - Running <TaskInstance: test.merge_df manual__2023-12-10T12:33:28.883629+00:00 [running]> on host xypma-VirtualBox
[2023-12-10T17:38:52.463+0500] {taskinstance.py:1662} INFO - Exporting env vars: AIRFLOW_CTX_DAG_OWNER='admin' AIRFLOW_CTX_DAG_ID='test' AIRFLOW_CTX_TASK_ID='merge_df' AIRFLOW_CTX_EXECUTION_DATE='2023-12-10T12:33:28.883629+00:00' AIRFLOW_CTX_TRY_NUMBER='2' AIRFLOW_CTX_DAG_RUN_ID='manual__2023-12-10T12:33:28.883629+00:00'
[2023-12-10T17:38:52.468+0500] {subprocess.py:63} INFO - Tmp dir root location: /tmp
[2023-12-10T17:38:52.469+0500] {subprocess.py:75} INFO - Running command: ['/usr/bin/bash', '-c', 'python /home/xypma/lab3/MLOps_lab3/scripts/merge_df.py']
[2023-12-10T17:38:52.482+0500] {subprocess.py:86} INFO - Output:
[2023-12-10T17:38:53.923+0500] {subprocess.py:93} INFO - Traceback (most recent call last):
[2023-12-10T17:38:53.928+0500] {subprocess.py:93} INFO -   File "/home/xypma/lab3/MLOps_lab3/scripts/merge_df.py", line 26, in <module>
[2023-12-10T17:38:53.928+0500] {subprocess.py:93} INFO -     merged.to_csv('/home/xypma/lab3/MLOps_lab3/datasets/stage1/train.csv', encoding='utf-8')
[2023-12-10T17:38:53.929+0500] {subprocess.py:93} INFO -   File "/home/xypma/lab3/MLOps_lab3/virt/lib/python3.10/site-packages/pandas/core/generic.py", line 3902, in to_csv
[2023-12-10T17:38:53.929+0500] {subprocess.py:93} INFO -     return DataFrameRenderer(formatter).to_csv(
[2023-12-10T17:38:53.929+0500] {subprocess.py:93} INFO -   File "/home/xypma/lab3/MLOps_lab3/virt/lib/python3.10/site-packages/pandas/io/formats/format.py", line 1152, in to_csv
[2023-12-10T17:38:53.930+0500] {subprocess.py:93} INFO -     csv_formatter.save()
[2023-12-10T17:38:53.930+0500] {subprocess.py:93} INFO -   File "/home/xypma/lab3/MLOps_lab3/virt/lib/python3.10/site-packages/pandas/io/formats/csvs.py", line 247, in save
[2023-12-10T17:38:53.930+0500] {subprocess.py:93} INFO -     with get_handle(
[2023-12-10T17:38:53.930+0500] {subprocess.py:93} INFO -   File "/home/xypma/lab3/MLOps_lab3/virt/lib/python3.10/site-packages/pandas/io/common.py", line 739, in get_handle
[2023-12-10T17:38:53.930+0500] {subprocess.py:93} INFO -     check_parent_directory(str(handle))
[2023-12-10T17:38:53.931+0500] {subprocess.py:93} INFO -   File "/home/xypma/lab3/MLOps_lab3/virt/lib/python3.10/site-packages/pandas/io/common.py", line 604, in check_parent_directory
[2023-12-10T17:38:53.931+0500] {subprocess.py:93} INFO -     raise OSError(rf"Cannot save file into a non-existent directory: '{parent}'")
[2023-12-10T17:38:53.931+0500] {subprocess.py:93} INFO - OSError: Cannot save file into a non-existent directory: '/home/xypma/lab3/MLOps_lab3/datasets/stage1'
[2023-12-10T17:38:54.135+0500] {subprocess.py:97} INFO - Command exited with return code 1
[2023-12-10T17:38:54.151+0500] {taskinstance.py:1937} ERROR - Task failed with exception
Traceback (most recent call last):
  File "/home/xypma/lab3/MLOps_lab3/virt/lib/python3.10/site-packages/airflow/operators/bash.py", line 210, in execute
    raise AirflowException(
airflow.exceptions.AirflowException: Bash command failed. The command returned a non-zero exit code 1.
[2023-12-10T17:38:54.158+0500] {taskinstance.py:1400} INFO - Marking task as FAILED. dag_id=test, task_id=merge_df, execution_date=20231210T123328, start_date=20231210T123852, end_date=20231210T123854
[2023-12-10T17:38:54.193+0500] {standard_task_runner.py:104} ERROR - Failed to execute job 14 for task merge_df (Bash command failed. The command returned a non-zero exit code 1.; 7190)
[2023-12-10T17:38:54.214+0500] {local_task_job_runner.py:228} INFO - Task exited with return code 1
[2023-12-10T17:38:54.257+0500] {taskinstance.py:2778} INFO - 0 downstream tasks scheduled from follow-on schedule check
