[2023-12-10T17:33:47.555+0500] {taskinstance.py:1159} INFO - Dependencies all met for dep_context=non-requeueable deps ti=<TaskInstance: test.merge_df manual__2023-12-10T12:33:28.883629+00:00 [queued]>
[2023-12-10T17:33:47.565+0500] {taskinstance.py:1159} INFO - Dependencies all met for dep_context=requeueable deps ti=<TaskInstance: test.merge_df manual__2023-12-10T12:33:28.883629+00:00 [queued]>
[2023-12-10T17:33:47.565+0500] {taskinstance.py:1361} INFO - Starting attempt 1 of 2
[2023-12-10T17:33:47.593+0500] {taskinstance.py:1382} INFO - Executing <Task(BashOperator): merge_df> on 2023-12-10 12:33:28.883629+00:00
[2023-12-10T17:33:47.595+0500] {standard_task_runner.py:57} INFO - Started process 7122 to run task
[2023-12-10T17:33:47.602+0500] {standard_task_runner.py:84} INFO - Running: ['airflow', 'tasks', 'run', 'test', 'merge_df', 'manual__2023-12-10T12:33:28.883629+00:00', '--job-id', '10', '--raw', '--subdir', 'DAGS_FOLDER/test.py', '--cfg-path', '/tmp/tmpymvs4sga']
[2023-12-10T17:33:47.607+0500] {standard_task_runner.py:85} INFO - Job 10: Subtask merge_df
[2023-12-10T17:33:47.668+0500] {task_command.py:416} INFO - Running <TaskInstance: test.merge_df manual__2023-12-10T12:33:28.883629+00:00 [running]> on host xypma-VirtualBox
[2023-12-10T17:33:47.762+0500] {taskinstance.py:1662} INFO - Exporting env vars: AIRFLOW_CTX_DAG_OWNER='admin' AIRFLOW_CTX_DAG_ID='test' AIRFLOW_CTX_TASK_ID='merge_df' AIRFLOW_CTX_EXECUTION_DATE='2023-12-10T12:33:28.883629+00:00' AIRFLOW_CTX_TRY_NUMBER='1' AIRFLOW_CTX_DAG_RUN_ID='manual__2023-12-10T12:33:28.883629+00:00'
[2023-12-10T17:33:47.765+0500] {subprocess.py:63} INFO - Tmp dir root location: /tmp
[2023-12-10T17:33:47.765+0500] {subprocess.py:75} INFO - Running command: ['/usr/bin/bash', '-c', 'python /home/xypma/lab3/MLOps_lab3/scripts/merge_df.py']
[2023-12-10T17:33:47.776+0500] {subprocess.py:86} INFO - Output:
[2023-12-10T17:33:49.338+0500] {subprocess.py:93} INFO - Traceback (most recent call last):
[2023-12-10T17:33:49.339+0500] {subprocess.py:93} INFO -   File "/home/xypma/lab3/MLOps_lab3/scripts/merge_df.py", line 4, in <module>
[2023-12-10T17:33:49.339+0500] {subprocess.py:93} INFO -     df_games = pd.read_csv('/home/xypma/lab3/MLOps_lab3/datasets/raw/games.csv')
[2023-12-10T17:33:49.339+0500] {subprocess.py:93} INFO -   File "/home/xypma/lab3/MLOps_lab3/virt/lib/python3.10/site-packages/pandas/io/parsers/readers.py", line 948, in read_csv
[2023-12-10T17:33:49.345+0500] {subprocess.py:93} INFO -     return _read(filepath_or_buffer, kwds)
[2023-12-10T17:33:49.345+0500] {subprocess.py:93} INFO -   File "/home/xypma/lab3/MLOps_lab3/virt/lib/python3.10/site-packages/pandas/io/parsers/readers.py", line 611, in _read
[2023-12-10T17:33:49.345+0500] {subprocess.py:93} INFO -     parser = TextFileReader(filepath_or_buffer, **kwds)
[2023-12-10T17:33:49.346+0500] {subprocess.py:93} INFO -   File "/home/xypma/lab3/MLOps_lab3/virt/lib/python3.10/site-packages/pandas/io/parsers/readers.py", line 1448, in __init__
[2023-12-10T17:33:49.346+0500] {subprocess.py:93} INFO -     self._engine = self._make_engine(f, self.engine)
[2023-12-10T17:33:49.346+0500] {subprocess.py:93} INFO -   File "/home/xypma/lab3/MLOps_lab3/virt/lib/python3.10/site-packages/pandas/io/parsers/readers.py", line 1705, in _make_engine
[2023-12-10T17:33:49.347+0500] {subprocess.py:93} INFO -     self.handles = get_handle(
[2023-12-10T17:33:49.347+0500] {subprocess.py:93} INFO -   File "/home/xypma/lab3/MLOps_lab3/virt/lib/python3.10/site-packages/pandas/io/common.py", line 863, in get_handle
[2023-12-10T17:33:49.348+0500] {subprocess.py:93} INFO -     handle = open(
[2023-12-10T17:33:49.348+0500] {subprocess.py:93} INFO - FileNotFoundError: [Errno 2] No such file or directory: '/home/xypma/lab3/MLOps_lab3/datasets/raw/games.csv'
[2023-12-10T17:33:49.542+0500] {subprocess.py:97} INFO - Command exited with return code 1
[2023-12-10T17:33:49.558+0500] {taskinstance.py:1937} ERROR - Task failed with exception
Traceback (most recent call last):
  File "/home/xypma/lab3/MLOps_lab3/virt/lib/python3.10/site-packages/airflow/operators/bash.py", line 210, in execute
    raise AirflowException(
airflow.exceptions.AirflowException: Bash command failed. The command returned a non-zero exit code 1.
[2023-12-10T17:33:49.568+0500] {taskinstance.py:1400} INFO - Marking task as UP_FOR_RETRY. dag_id=test, task_id=merge_df, execution_date=20231210T123328, start_date=20231210T123347, end_date=20231210T123349
[2023-12-10T17:33:49.596+0500] {standard_task_runner.py:104} ERROR - Failed to execute job 10 for task merge_df (Bash command failed. The command returned a non-zero exit code 1.; 7122)
[2023-12-10T17:33:49.661+0500] {local_task_job_runner.py:228} INFO - Task exited with return code 1
[2023-12-10T17:33:49.716+0500] {taskinstance.py:2778} INFO - 0 downstream tasks scheduled from follow-on schedule check
