[2023-12-10T17:51:46.235+0500] {taskinstance.py:1159} INFO - Dependencies all met for dep_context=non-requeueable deps ti=<TaskInstance: test.train_test_split manual__2023-12-10T12:51:10.603168+00:00 [queued]>
[2023-12-10T17:51:46.271+0500] {taskinstance.py:1159} INFO - Dependencies all met for dep_context=requeueable deps ti=<TaskInstance: test.train_test_split manual__2023-12-10T12:51:10.603168+00:00 [queued]>
[2023-12-10T17:51:46.272+0500] {taskinstance.py:1361} INFO - Starting attempt 1 of 2
[2023-12-10T17:51:46.298+0500] {taskinstance.py:1382} INFO - Executing <Task(BashOperator): train_test_split> on 2023-12-10 12:51:10.603168+00:00
[2023-12-10T17:51:46.301+0500] {standard_task_runner.py:57} INFO - Started process 7394 to run task
[2023-12-10T17:51:46.318+0500] {standard_task_runner.py:84} INFO - Running: ['airflow', 'tasks', 'run', 'test', 'train_test_split', 'manual__2023-12-10T12:51:10.603168+00:00', '--job-id', '31', '--raw', '--subdir', 'DAGS_FOLDER/test.py', '--cfg-path', '/tmp/tmp_ncxlp82']
[2023-12-10T17:51:46.321+0500] {standard_task_runner.py:85} INFO - Job 31: Subtask train_test_split
[2023-12-10T17:51:46.405+0500] {task_command.py:416} INFO - Running <TaskInstance: test.train_test_split manual__2023-12-10T12:51:10.603168+00:00 [running]> on host xypma-VirtualBox
[2023-12-10T17:51:46.505+0500] {taskinstance.py:1662} INFO - Exporting env vars: AIRFLOW_CTX_DAG_OWNER='admin' AIRFLOW_CTX_DAG_ID='test' AIRFLOW_CTX_TASK_ID='train_test_split' AIRFLOW_CTX_EXECUTION_DATE='2023-12-10T12:51:10.603168+00:00' AIRFLOW_CTX_TRY_NUMBER='1' AIRFLOW_CTX_DAG_RUN_ID='manual__2023-12-10T12:51:10.603168+00:00'
[2023-12-10T17:51:46.506+0500] {subprocess.py:63} INFO - Tmp dir root location: /tmp
[2023-12-10T17:51:46.507+0500] {subprocess.py:75} INFO - Running command: ['/usr/bin/bash', '-c', 'cd /home/xypma/lab3/MLOps_lab3/ && python /home/xypma/lab3/MLOps_lab3/scripts/train_test_split.py']
[2023-12-10T17:51:46.520+0500] {subprocess.py:86} INFO - Output:
[2023-12-10T17:51:48.912+0500] {subprocess.py:93} INFO - Traceback (most recent call last):
[2023-12-10T17:51:48.912+0500] {subprocess.py:93} INFO -   File "/home/xypma/lab3/MLOps_lab3/scripts/train_test_split.py", line 6, in <module>
[2023-12-10T17:51:48.912+0500] {subprocess.py:93} INFO -     df = pd.read_csv('/home/xypma/lab3/MLOps_lab3/datasets/stage3/train.csv')
[2023-12-10T17:51:48.913+0500] {subprocess.py:93} INFO -   File "/home/xypma/lab3/MLOps_lab3/virt/lib/python3.10/site-packages/pandas/io/parsers/readers.py", line 948, in read_csv
[2023-12-10T17:51:48.913+0500] {subprocess.py:93} INFO -     return _read(filepath_or_buffer, kwds)
[2023-12-10T17:51:48.913+0500] {subprocess.py:93} INFO -   File "/home/xypma/lab3/MLOps_lab3/virt/lib/python3.10/site-packages/pandas/io/parsers/readers.py", line 611, in _read
[2023-12-10T17:51:48.913+0500] {subprocess.py:93} INFO -     parser = TextFileReader(filepath_or_buffer, **kwds)
[2023-12-10T17:51:48.913+0500] {subprocess.py:93} INFO -   File "/home/xypma/lab3/MLOps_lab3/virt/lib/python3.10/site-packages/pandas/io/parsers/readers.py", line 1448, in __init__
[2023-12-10T17:51:48.914+0500] {subprocess.py:93} INFO -     self._engine = self._make_engine(f, self.engine)
[2023-12-10T17:51:48.914+0500] {subprocess.py:93} INFO -   File "/home/xypma/lab3/MLOps_lab3/virt/lib/python3.10/site-packages/pandas/io/parsers/readers.py", line 1705, in _make_engine
[2023-12-10T17:51:48.914+0500] {subprocess.py:93} INFO -     self.handles = get_handle(
[2023-12-10T17:51:48.916+0500] {subprocess.py:93} INFO -   File "/home/xypma/lab3/MLOps_lab3/virt/lib/python3.10/site-packages/pandas/io/common.py", line 863, in get_handle
[2023-12-10T17:51:48.916+0500] {subprocess.py:93} INFO -     handle = open(
[2023-12-10T17:51:48.916+0500] {subprocess.py:93} INFO - FileNotFoundError: [Errno 2] No such file or directory: '/home/xypma/lab3/MLOps_lab3/datasets/stage3/train.csv'
[2023-12-10T17:51:49.257+0500] {subprocess.py:97} INFO - Command exited with return code 1
[2023-12-10T17:51:49.274+0500] {taskinstance.py:1937} ERROR - Task failed with exception
Traceback (most recent call last):
  File "/home/xypma/lab3/MLOps_lab3/virt/lib/python3.10/site-packages/airflow/operators/bash.py", line 210, in execute
    raise AirflowException(
airflow.exceptions.AirflowException: Bash command failed. The command returned a non-zero exit code 1.
[2023-12-10T17:51:49.278+0500] {taskinstance.py:1400} INFO - Marking task as UP_FOR_RETRY. dag_id=test, task_id=train_test_split, execution_date=20231210T125110, start_date=20231210T125146, end_date=20231210T125149
[2023-12-10T17:51:49.306+0500] {standard_task_runner.py:104} ERROR - Failed to execute job 31 for task train_test_split (Bash command failed. The command returned a non-zero exit code 1.; 7394)
[2023-12-10T17:51:49.332+0500] {local_task_job_runner.py:228} INFO - Task exited with return code 1
[2023-12-10T17:51:49.367+0500] {taskinstance.py:2778} INFO - 0 downstream tasks scheduled from follow-on schedule check
