[2023-12-10T17:41:49.409+0500] {taskinstance.py:1159} INFO - Dependencies all met for dep_context=non-requeueable deps ti=<TaskInstance: test.clear_features manual__2023-12-10T12:36:18.011733+00:00 [queued]>
[2023-12-10T17:41:49.436+0500] {taskinstance.py:1159} INFO - Dependencies all met for dep_context=requeueable deps ti=<TaskInstance: test.clear_features manual__2023-12-10T12:36:18.011733+00:00 [queued]>
[2023-12-10T17:41:49.436+0500] {taskinstance.py:1361} INFO - Starting attempt 1 of 2
[2023-12-10T17:41:49.469+0500] {taskinstance.py:1382} INFO - Executing <Task(BashOperator): clear_features> on 2023-12-10 12:36:18.011733+00:00
[2023-12-10T17:41:49.474+0500] {standard_task_runner.py:57} INFO - Started process 7233 to run task
[2023-12-10T17:41:49.502+0500] {standard_task_runner.py:84} INFO - Running: ['airflow', 'tasks', 'run', 'test', 'clear_features', 'manual__2023-12-10T12:36:18.011733+00:00', '--job-id', '16', '--raw', '--subdir', 'DAGS_FOLDER/test.py', '--cfg-path', '/tmp/tmpqc21m7ds']
[2023-12-10T17:41:49.504+0500] {standard_task_runner.py:85} INFO - Job 16: Subtask clear_features
[2023-12-10T17:41:49.625+0500] {task_command.py:416} INFO - Running <TaskInstance: test.clear_features manual__2023-12-10T12:36:18.011733+00:00 [running]> on host xypma-VirtualBox
[2023-12-10T17:41:49.759+0500] {taskinstance.py:1662} INFO - Exporting env vars: AIRFLOW_CTX_DAG_OWNER='admin' AIRFLOW_CTX_DAG_ID='test' AIRFLOW_CTX_TASK_ID='clear_features' AIRFLOW_CTX_EXECUTION_DATE='2023-12-10T12:36:18.011733+00:00' AIRFLOW_CTX_TRY_NUMBER='1' AIRFLOW_CTX_DAG_RUN_ID='manual__2023-12-10T12:36:18.011733+00:00'
[2023-12-10T17:41:49.763+0500] {subprocess.py:63} INFO - Tmp dir root location: /tmp
[2023-12-10T17:41:49.763+0500] {subprocess.py:75} INFO - Running command: ['/usr/bin/bash', '-c', 'python /home/xypma/lab3/MLOps_lab3/scripts/clear_features.py']
[2023-12-10T17:41:49.779+0500] {subprocess.py:86} INFO - Output:
[2023-12-10T17:41:50.719+0500] {subprocess.py:93} INFO - Traceback (most recent call last):
[2023-12-10T17:41:50.728+0500] {subprocess.py:93} INFO -   File "/home/xypma/lab3/MLOps_lab3/scripts/clear_features.py", line 5, in <module>
[2023-12-10T17:41:50.729+0500] {subprocess.py:93} INFO -     df = pd.read_csv('/home/xypma/lab3/MLOps_lab3/datasets/stage1/train.csv')
[2023-12-10T17:41:50.729+0500] {subprocess.py:93} INFO -   File "/home/xypma/lab3/MLOps_lab3/virt/lib/python3.10/site-packages/pandas/io/parsers/readers.py", line 948, in read_csv
[2023-12-10T17:41:50.729+0500] {subprocess.py:93} INFO -     return _read(filepath_or_buffer, kwds)
[2023-12-10T17:41:50.729+0500] {subprocess.py:93} INFO -   File "/home/xypma/lab3/MLOps_lab3/virt/lib/python3.10/site-packages/pandas/io/parsers/readers.py", line 611, in _read
[2023-12-10T17:41:50.730+0500] {subprocess.py:93} INFO -     parser = TextFileReader(filepath_or_buffer, **kwds)
[2023-12-10T17:41:50.732+0500] {subprocess.py:93} INFO -   File "/home/xypma/lab3/MLOps_lab3/virt/lib/python3.10/site-packages/pandas/io/parsers/readers.py", line 1448, in __init__
[2023-12-10T17:41:50.732+0500] {subprocess.py:93} INFO -     self._engine = self._make_engine(f, self.engine)
[2023-12-10T17:41:50.732+0500] {subprocess.py:93} INFO -   File "/home/xypma/lab3/MLOps_lab3/virt/lib/python3.10/site-packages/pandas/io/parsers/readers.py", line 1705, in _make_engine
[2023-12-10T17:41:50.733+0500] {subprocess.py:93} INFO -     self.handles = get_handle(
[2023-12-10T17:41:50.733+0500] {subprocess.py:93} INFO -   File "/home/xypma/lab3/MLOps_lab3/virt/lib/python3.10/site-packages/pandas/io/common.py", line 863, in get_handle
[2023-12-10T17:41:50.733+0500] {subprocess.py:93} INFO -     handle = open(
[2023-12-10T17:41:50.733+0500] {subprocess.py:93} INFO - FileNotFoundError: [Errno 2] No such file or directory: '/home/xypma/lab3/MLOps_lab3/datasets/stage1/train.csv'
[2023-12-10T17:41:50.926+0500] {subprocess.py:97} INFO - Command exited with return code 1
[2023-12-10T17:41:50.940+0500] {taskinstance.py:1937} ERROR - Task failed with exception
Traceback (most recent call last):
  File "/home/xypma/lab3/MLOps_lab3/virt/lib/python3.10/site-packages/airflow/operators/bash.py", line 210, in execute
    raise AirflowException(
airflow.exceptions.AirflowException: Bash command failed. The command returned a non-zero exit code 1.
[2023-12-10T17:41:50.950+0500] {taskinstance.py:1400} INFO - Marking task as UP_FOR_RETRY. dag_id=test, task_id=clear_features, execution_date=20231210T123618, start_date=20231210T124149, end_date=20231210T124150
[2023-12-10T17:41:50.980+0500] {standard_task_runner.py:104} ERROR - Failed to execute job 16 for task clear_features (Bash command failed. The command returned a non-zero exit code 1.; 7233)
[2023-12-10T17:41:51.000+0500] {local_task_job_runner.py:228} INFO - Task exited with return code 1
[2023-12-10T17:41:51.032+0500] {taskinstance.py:2778} INFO - 0 downstream tasks scheduled from follow-on schedule check
