[2023-12-10T17:50:23.936+0500] {taskinstance.py:1159} INFO - Dependencies all met for dep_context=non-requeueable deps ti=<TaskInstance: test.clear_features manual__2023-12-10T12:50:00.737361+00:00 [queued]>
[2023-12-10T17:50:23.957+0500] {taskinstance.py:1159} INFO - Dependencies all met for dep_context=requeueable deps ti=<TaskInstance: test.clear_features manual__2023-12-10T12:50:00.737361+00:00 [queued]>
[2023-12-10T17:50:23.957+0500] {taskinstance.py:1361} INFO - Starting attempt 1 of 2
[2023-12-10T17:50:23.984+0500] {taskinstance.py:1382} INFO - Executing <Task(BashOperator): clear_features> on 2023-12-10 12:50:00.737361+00:00
[2023-12-10T17:50:23.987+0500] {standard_task_runner.py:57} INFO - Started process 7335 to run task
[2023-12-10T17:50:24.006+0500] {standard_task_runner.py:84} INFO - Running: ['airflow', 'tasks', 'run', 'test', 'clear_features', 'manual__2023-12-10T12:50:00.737361+00:00', '--job-id', '25', '--raw', '--subdir', 'DAGS_FOLDER/test.py', '--cfg-path', '/tmp/tmpzj4m4yxl']
[2023-12-10T17:50:24.009+0500] {standard_task_runner.py:85} INFO - Job 25: Subtask clear_features
[2023-12-10T17:50:24.095+0500] {task_command.py:416} INFO - Running <TaskInstance: test.clear_features manual__2023-12-10T12:50:00.737361+00:00 [running]> on host xypma-VirtualBox
[2023-12-10T17:50:24.217+0500] {taskinstance.py:1662} INFO - Exporting env vars: AIRFLOW_CTX_DAG_OWNER='admin' AIRFLOW_CTX_DAG_ID='test' AIRFLOW_CTX_TASK_ID='clear_features' AIRFLOW_CTX_EXECUTION_DATE='2023-12-10T12:50:00.737361+00:00' AIRFLOW_CTX_TRY_NUMBER='1' AIRFLOW_CTX_DAG_RUN_ID='manual__2023-12-10T12:50:00.737361+00:00'
[2023-12-10T17:50:24.218+0500] {subprocess.py:63} INFO - Tmp dir root location: /tmp
[2023-12-10T17:50:24.220+0500] {subprocess.py:75} INFO - Running command: ['/usr/bin/bash', '-c', 'python /home/xypma/lab3/MLOps_lab3/scripts/clear_features.py']
[2023-12-10T17:50:24.238+0500] {subprocess.py:86} INFO - Output:
[2023-12-10T17:50:25.468+0500] {subprocess.py:93} INFO - Traceback (most recent call last):
[2023-12-10T17:50:25.469+0500] {subprocess.py:93} INFO -   File "/home/xypma/lab3/MLOps_lab3/scripts/clear_features.py", line 10, in <module>
[2023-12-10T17:50:25.469+0500] {subprocess.py:93} INFO -     df.to_csv('/home/xypma/lab3/MLOps_lab3/data/stage2/train.csv', encoding='utf-8')
[2023-12-10T17:50:25.469+0500] {subprocess.py:93} INFO -   File "/home/xypma/lab3/MLOps_lab3/virt/lib/python3.10/site-packages/pandas/core/generic.py", line 3902, in to_csv
[2023-12-10T17:50:25.469+0500] {subprocess.py:93} INFO -     return DataFrameRenderer(formatter).to_csv(
[2023-12-10T17:50:25.471+0500] {subprocess.py:93} INFO -   File "/home/xypma/lab3/MLOps_lab3/virt/lib/python3.10/site-packages/pandas/io/formats/format.py", line 1152, in to_csv
[2023-12-10T17:50:25.471+0500] {subprocess.py:93} INFO -     csv_formatter.save()
[2023-12-10T17:50:25.471+0500] {subprocess.py:93} INFO -   File "/home/xypma/lab3/MLOps_lab3/virt/lib/python3.10/site-packages/pandas/io/formats/csvs.py", line 247, in save
[2023-12-10T17:50:25.472+0500] {subprocess.py:93} INFO -     with get_handle(
[2023-12-10T17:50:25.472+0500] {subprocess.py:93} INFO -   File "/home/xypma/lab3/MLOps_lab3/virt/lib/python3.10/site-packages/pandas/io/common.py", line 739, in get_handle
[2023-12-10T17:50:25.472+0500] {subprocess.py:93} INFO -     check_parent_directory(str(handle))
[2023-12-10T17:50:25.472+0500] {subprocess.py:93} INFO -   File "/home/xypma/lab3/MLOps_lab3/virt/lib/python3.10/site-packages/pandas/io/common.py", line 604, in check_parent_directory
[2023-12-10T17:50:25.472+0500] {subprocess.py:93} INFO -     raise OSError(rf"Cannot save file into a non-existent directory: '{parent}'")
[2023-12-10T17:50:25.473+0500] {subprocess.py:93} INFO - OSError: Cannot save file into a non-existent directory: '/home/xypma/lab3/MLOps_lab3/data/stage2'
[2023-12-10T17:50:25.623+0500] {subprocess.py:97} INFO - Command exited with return code 1
[2023-12-10T17:50:25.639+0500] {taskinstance.py:1937} ERROR - Task failed with exception
Traceback (most recent call last):
  File "/home/xypma/lab3/MLOps_lab3/virt/lib/python3.10/site-packages/airflow/operators/bash.py", line 210, in execute
    raise AirflowException(
airflow.exceptions.AirflowException: Bash command failed. The command returned a non-zero exit code 1.
[2023-12-10T17:50:25.646+0500] {taskinstance.py:1400} INFO - Marking task as UP_FOR_RETRY. dag_id=test, task_id=clear_features, execution_date=20231210T125000, start_date=20231210T125023, end_date=20231210T125025
[2023-12-10T17:50:25.677+0500] {standard_task_runner.py:104} ERROR - Failed to execute job 25 for task clear_features (Bash command failed. The command returned a non-zero exit code 1.; 7335)
[2023-12-10T17:50:25.733+0500] {local_task_job_runner.py:228} INFO - Task exited with return code 1
[2023-12-10T17:50:25.769+0500] {taskinstance.py:2778} INFO - 0 downstream tasks scheduled from follow-on schedule check
