[2023-12-10T17:36:39.110+0500] {taskinstance.py:1159} INFO - Dependencies all met for dep_context=non-requeueable deps ti=<TaskInstance: test.merge_df manual__2023-12-10T12:36:18.011733+00:00 [queued]>
[2023-12-10T17:36:39.132+0500] {taskinstance.py:1159} INFO - Dependencies all met for dep_context=requeueable deps ti=<TaskInstance: test.merge_df manual__2023-12-10T12:36:18.011733+00:00 [queued]>
[2023-12-10T17:36:39.132+0500] {taskinstance.py:1361} INFO - Starting attempt 1 of 2
[2023-12-10T17:36:39.156+0500] {taskinstance.py:1382} INFO - Executing <Task(BashOperator): merge_df> on 2023-12-10 12:36:18.011733+00:00
[2023-12-10T17:36:39.159+0500] {standard_task_runner.py:57} INFO - Started process 7168 to run task
[2023-12-10T17:36:39.176+0500] {standard_task_runner.py:84} INFO - Running: ['airflow', 'tasks', 'run', 'test', 'merge_df', 'manual__2023-12-10T12:36:18.011733+00:00', '--job-id', '13', '--raw', '--subdir', 'DAGS_FOLDER/test.py', '--cfg-path', '/tmp/tmpcsdnsunu']
[2023-12-10T17:36:39.177+0500] {standard_task_runner.py:85} INFO - Job 13: Subtask merge_df
[2023-12-10T17:36:39.252+0500] {task_command.py:416} INFO - Running <TaskInstance: test.merge_df manual__2023-12-10T12:36:18.011733+00:00 [running]> on host xypma-VirtualBox
[2023-12-10T17:36:39.401+0500] {taskinstance.py:1662} INFO - Exporting env vars: AIRFLOW_CTX_DAG_OWNER='admin' AIRFLOW_CTX_DAG_ID='test' AIRFLOW_CTX_TASK_ID='merge_df' AIRFLOW_CTX_EXECUTION_DATE='2023-12-10T12:36:18.011733+00:00' AIRFLOW_CTX_TRY_NUMBER='1' AIRFLOW_CTX_DAG_RUN_ID='manual__2023-12-10T12:36:18.011733+00:00'
[2023-12-10T17:36:39.402+0500] {subprocess.py:63} INFO - Tmp dir root location: /tmp
[2023-12-10T17:36:39.413+0500] {subprocess.py:75} INFO - Running command: ['/usr/bin/bash', '-c', 'python /home/xypma/lab3/MLOps_lab3/scripts/merge_df.py']
[2023-12-10T17:36:39.428+0500] {subprocess.py:86} INFO - Output:
[2023-12-10T17:36:40.880+0500] {subprocess.py:93} INFO - Traceback (most recent call last):
[2023-12-10T17:36:40.881+0500] {subprocess.py:93} INFO -   File "/home/xypma/lab3/MLOps_lab3/scripts/merge_df.py", line 26, in <module>
[2023-12-10T17:36:40.881+0500] {subprocess.py:93} INFO -     merged.to_csv('/home/xypma/lab3/MLOps_lab3/datasets/stage1/train.csv', encoding='utf-8')
[2023-12-10T17:36:40.881+0500] {subprocess.py:93} INFO -   File "/home/xypma/lab3/MLOps_lab3/virt/lib/python3.10/site-packages/pandas/core/generic.py", line 3902, in to_csv
[2023-12-10T17:36:40.883+0500] {subprocess.py:93} INFO -     return DataFrameRenderer(formatter).to_csv(
[2023-12-10T17:36:40.884+0500] {subprocess.py:93} INFO -   File "/home/xypma/lab3/MLOps_lab3/virt/lib/python3.10/site-packages/pandas/io/formats/format.py", line 1152, in to_csv
[2023-12-10T17:36:40.889+0500] {subprocess.py:93} INFO -     csv_formatter.save()
[2023-12-10T17:36:40.889+0500] {subprocess.py:93} INFO -   File "/home/xypma/lab3/MLOps_lab3/virt/lib/python3.10/site-packages/pandas/io/formats/csvs.py", line 247, in save
[2023-12-10T17:36:40.892+0500] {subprocess.py:93} INFO -     with get_handle(
[2023-12-10T17:36:40.892+0500] {subprocess.py:93} INFO -   File "/home/xypma/lab3/MLOps_lab3/virt/lib/python3.10/site-packages/pandas/io/common.py", line 739, in get_handle
[2023-12-10T17:36:40.892+0500] {subprocess.py:93} INFO -     check_parent_directory(str(handle))
[2023-12-10T17:36:40.892+0500] {subprocess.py:93} INFO -   File "/home/xypma/lab3/MLOps_lab3/virt/lib/python3.10/site-packages/pandas/io/common.py", line 604, in check_parent_directory
[2023-12-10T17:36:40.892+0500] {subprocess.py:93} INFO -     raise OSError(rf"Cannot save file into a non-existent directory: '{parent}'")
[2023-12-10T17:36:40.892+0500] {subprocess.py:93} INFO - OSError: Cannot save file into a non-existent directory: '/home/xypma/lab3/MLOps_lab3/datasets/stage1'
[2023-12-10T17:36:41.079+0500] {subprocess.py:97} INFO - Command exited with return code 1
[2023-12-10T17:36:41.092+0500] {taskinstance.py:1937} ERROR - Task failed with exception
Traceback (most recent call last):
  File "/home/xypma/lab3/MLOps_lab3/virt/lib/python3.10/site-packages/airflow/operators/bash.py", line 210, in execute
    raise AirflowException(
airflow.exceptions.AirflowException: Bash command failed. The command returned a non-zero exit code 1.
[2023-12-10T17:36:41.097+0500] {taskinstance.py:1400} INFO - Marking task as UP_FOR_RETRY. dag_id=test, task_id=merge_df, execution_date=20231210T123618, start_date=20231210T123639, end_date=20231210T123641
[2023-12-10T17:36:41.126+0500] {standard_task_runner.py:104} ERROR - Failed to execute job 13 for task merge_df (Bash command failed. The command returned a non-zero exit code 1.; 7168)
[2023-12-10T17:36:41.145+0500] {local_task_job_runner.py:228} INFO - Task exited with return code 1
[2023-12-10T17:36:41.182+0500] {taskinstance.py:2778} INFO - 0 downstream tasks scheduled from follow-on schedule check
